<?xml version="1.0" ?>
<!--
  Webots-side URDF for the Mowgli mower.

  This URDF mirrors the kinematic structure of the inline Robot {} node
  in worlds_webots/mowgli_garden.wbt:
    * chassis (base_link) at z = 0.10
    * two rear drive wheels at ±0.1625 m on Y, axis along Y, radius 0.093
    * two front passive casters (kept simple here as fixed mounts; they
      are real BallJoints in the .wbt, so the wheel TFs published by RSP
      from this URDF will be slightly off in pitch — irrelevant to the
      navigation stack which ignores caster TFs).
    * sensor frames (lidar, imu, gps) matching the Webots device
      placements

  It is consumed by:
    * hardware_interface — needs <joint name="…"/> elements for every
      ros2_control joint to extract joint limits (kilted+ requirement).
    * robot_state_publisher — publishes the static TF tree from the
      <joint> elements + the joint_state_broadcaster's wheel positions.
    * webots_ros2_driver / webots_ros2_control — wires Webots devices
      (declared in the <webots> block below) to ROS2, and binds
      Webots motors to ros2_control joints by name.

  base_link == base_footprint here (flat outdoor mower, no significant
  tilt). diff_drive_controller publishes odometry with
  child_frame_id="base_footprint", which we satisfy by the explicit
  fixed joint base_link → base_footprint below.
-->
<robot name="MowgliMower">

  <!-- ── Kinematic structure ───────────────────────────────────────── -->
  <!--
    Inertials are intentionally omitted on the chassis: the actual
    physics is owned by the inline Robot {} in mowgli_garden.wbt
    (Webots' physics engine), and KDL warns when the URDF root link
    carries an <inertial> block. URDF visual/collision are kept so
    that downstream tools (RViz, Foxglove, MoveIt) render correctly.
  -->
  <link name="base_link">
    <visual>
      <origin xyz="0 0 0" rpy="0 0 0"/>
      <geometry>
        <box size="0.60 0.40 0.19"/>
      </geometry>
    </visual>
    <collision>
      <origin xyz="0 0 0" rpy="0 0 0"/>
      <geometry>
        <box size="0.60 0.40 0.19"/>
      </geometry>
    </collision>
  </link>

  <!-- REP-105: base_footprint is on the ground, base_link above it.
       odom→base_footprint is published by ekf_odom_node (Phase 2 sim
       and production). RSP must therefore make base_footprint the
       PARENT of base_link, otherwise base_footprint has two parents
       (odom AND base_link) and tf2 silently picks one — Nav2 lookups
       then resolve against a stale or wrong chain.

       Phase 1 worked with the old direction because no ekf_odom was
       running; Phase 2 brings it up. Inline Robot {} in mowgli_garden.wbt
       sits at world z=0.10, so base_footprint at world z=0 ⇒ base_link
       offset of +0.10 m above base_footprint. -->
  <link name="base_footprint"/>
  <joint name="base_footprint_to_base_link" type="fixed">
    <parent link="base_footprint"/>
    <child link="base_link"/>
    <origin xyz="0 0 0.10" rpy="0 0 0"/>
  </joint>

  <!-- Left rear drive wheel (physics in .wbt — see comment on base_link). -->
  <link name="left_wheel">
    <visual>
      <origin xyz="0 0 0" rpy="1.5708 0 0"/>
      <geometry>
        <cylinder length="0.04" radius="0.093"/>
      </geometry>
    </visual>
    <collision>
      <origin xyz="0 0 0" rpy="1.5708 0 0"/>
      <geometry>
        <cylinder length="0.04" radius="0.093"/>
      </geometry>
    </collision>
  </link>
  <joint name="left_wheel_motor" type="continuous">
    <parent link="base_link"/>
    <child link="left_wheel"/>
    <!-- Wheel HingeJoint anchor matches the PROTO (robot frame z=0.093,
         which is base_link frame z=-0.007 because base_link sits at
         world z=0.10 while the wheel centre sits at world z=0.093 —
         wheel-bottom flush with the floor at z=0). Phase 2.1 moved
         wheels out of the floor: previously they were "half-buried"
         (centre at z=0) which produced 30-45° chassis tip / wheel slip
         under cmd_vel acceleration. The PROTO follows TurtleBot3Burger's
         design (wheels and casters share the same ground-contact z) —
         no penetration impulses, no tip pathology. -->
    <origin xyz="0 0.1625 -0.007" rpy="0 0 0"/>
    <axis xyz="0 1 0"/>
    <limit effort="20.0" velocity="100.0"/>
  </joint>

  <!-- Right rear drive wheel (physics in .wbt — see comment on base_link). -->
  <link name="right_wheel">
    <visual>
      <origin xyz="0 0 0" rpy="1.5708 0 0"/>
      <geometry>
        <cylinder length="0.04" radius="0.093"/>
      </geometry>
    </visual>
    <collision>
      <origin xyz="0 0 0" rpy="1.5708 0 0"/>
      <geometry>
        <cylinder length="0.04" radius="0.093"/>
      </geometry>
    </collision>
  </link>
  <joint name="right_wheel_motor" type="continuous">
    <parent link="base_link"/>
    <child link="right_wheel"/>
    <!-- See left_wheel_motor for the rationale on z=-0.007. -->
    <origin xyz="0 -0.1625 -0.007" rpy="0 0 0"/>
    <axis xyz="0 1 0"/>
    <limit effort="20.0" velocity="100.0"/>
  </joint>

  <!-- Sensor frames (static — RSP publishes these directly). -->
  <link name="lidar_link"/>
  <joint name="base_link_to_lidar" type="fixed">
    <parent link="base_link"/>
    <child link="lidar_link"/>
    <origin xyz="0 0.024 0.12" rpy="0 0 3.1408"/>
  </joint>

  <link name="imu_link"/>
  <joint name="base_link_to_imu" type="fixed">
    <parent link="base_link"/>
    <child link="imu_link"/>
    <origin xyz="0 0 0" rpy="0 0 0"/>
  </joint>

  <link name="gps_link"/>
  <joint name="base_link_to_gps" type="fixed">
    <parent link="base_link"/>
    <child link="gps_link"/>
    <origin xyz="0.30 0 0.10" rpy="0 0 0"/>
  </joint>

  <!-- ── Webots device + plugin wiring ─────────────────────────────── -->
  <webots>
    <device reference="lidar" type="Lidar">
      <ros>
        <enabled>true</enabled>
        <updateRate>10</updateRate>
        <topicName>/scan</topicName>
        <alwaysOn>true</alwaysOn>
        <frameName>lidar_link</frameName>
      </ros>
    </device>

    <device reference="gps" type="GPS">
      <ros>
        <enabled>true</enabled>
        <updateRate>5</updateRate>
        <topicName>/gps/fix_raw</topicName>
        <alwaysOn>true</alwaysOn>
        <frameName>gps_link</frameName>
      </ros>
    </device>

    <plugin type="webots_ros2_driver::Ros2IMU">
      <enabled>true</enabled>
      <updateRate>100</updateRate>
      <topicName>/imu/data_sim</topicName>
      <alwaysOn>true</alwaysOn>
      <frameName>imu_link</frameName>
      <inertialUnitName>inertial_unit</inertialUnitName>
      <gyroName>gyro</gyroName>
      <accelerometerName>accelerometer</accelerometerName>
    </plugin>

    <plugin type="webots_ros2_control::Ros2Control" />
  </webots>

  <!-- ── ros2_control joint declarations ───────────────────────────── -->
  <ros2_control name="WebotsControl" type="system">
    <hardware>
      <plugin>webots_ros2_control::Ros2ControlSystem</plugin>
    </hardware>
    <joint name="left_wheel_motor">
      <state_interface name="position"/>
      <state_interface name="velocity"/>
      <command_interface name="velocity"/>
    </joint>
    <joint name="right_wheel_motor">
      <state_interface name="position"/>
      <state_interface name="velocity"/>
      <command_interface name="velocity"/>
    </joint>
  </ros2_control>
</robot>
